Workbook

Sheet LEIA-ME
A1: Seckler Moving — Modelo financeiro de expansão (warehouse, storage, sinistros, governo)
A3: Como usar:
A4: 1. Edite apenas as células AZUIS na aba Premissas (e metas em KPIs).
A5: 2. A aba Cenarios recalcula 9 combinações: estruturas A/B/C x casos Conservador/Base/Otimista.
A6: 3. A aba Sensibilidade mostra quantos vaults estáveis justificam sair do modelo terceirizado.
A7: 4. CRM: altere Etapa pelo menu; Data follow-up = último contato + 7 dias (sobrescreva se precisar).
A8: 5. KPIs: uma linha por semana.
A10: Regras do modelo:
A11: - Valores são mensais, em regime (após rampa). Não há projeção de crescimento automática.
A12: - Receita de governo só entra quando houver contrato assinado.
A13: - Toda premissa sem fonte está marcada como PREMISSA ou PENDENTE na coluna F.
A14: - Não é recomendação de crédito nem garantia de aprovação de financiamento.
A16: Gerado por model/build_model.py — rode novamente para recriar a planilha a partir do código.

Sheet Premissas
A1: Premissas — células azuis são editáveis. Fonte/status na coluna F.
A3: Parâmetro (varia por CASO) | B3: Unidade | C3: Conservador | D3: Base | E3: Otimista | F3: Fonte / status
A4: Mudanças por mês | B4: jobs | C4: 24 | D4: 30 | E4: 36 | F4: Renan (17/10/2026): ~30 mudanças/mês com 2 caminhões. Conservador -20%, otimista +20%.
A5: Ticket médio por mudança | B5: US$ | C5: 900 | D5: 1000 | E5: 1100 | F5: Renan (17/10/2026): ticket médio ~US$1.000, mínimo US$450. Coerente com moveBuddha Orlando (US$672-1.550).
A6: Custo variável da mudança | B6: % receita | C6: 0.58 | D6: 0.55 | E6: 0.52 | F6: PREMISSA: mão de obra, combustível, materiais, comissões. Substituir pela DRE real.
A7: Pack-outs (sinistros) por mês | B7: jobs | C7: 0 | D7: 1 | E7: 3 | F7: PREMISSA: zero no conservador até existir parceiro de restauração assinado.
A8: Ticket médio pack-out + devolução (sem armazenagem) | B8: US$ | C8: 2500 | D8: 3500 | E8: 4500 | F8: Referência única de fornecedor (Maryland): US$1.500-6.500 por residência. Baixa confiança.
A9: Custo variável do pack-out | B9: % receita | C9: 0.55 | D9: 0.5 | E9: 0.45 | F9: PREMISSA: mão de obra intensiva, caixas, inventário, transporte.
A10: Vaults ocupados (média do período) | B10: vaults | C10: 8 | D10: 25 | E10: 50 | F10: PREMISSA: estoque médio de clientes em armazenagem (mudança + sinistro).
A11: Preço por vault / mês | B11: US$ | C11: 90 | D11: 110 | E11: 130 | F11: PREMISSA a validar por cotação oculta (1st Class, Suddath, Cento, J&J Metro). Self-storage 10x10 climatizado WG: ~US$80-155/mês (RentCafe/Public Storage 2026).
A12: Manuseio + seguro de armazenagem por vault / mês | B12: US$ | C12: 10 | D12: 8 | E12: 7 | F12: PREMISSA.
A13: Prazo médio de recebimento do pack-out (DSO) | B13: dias | C13: 75 | D13: 60 | E13: 45 | F13: PREMISSA: restauradoras/seguradoras pagam com atraso; validar nos contratos.
A14: Reserva de caixa | B14: meses de custo fixo | C14: 3 | D14: 2 | E14: 2 | F14: Política de prudência.
A15: Receita governo (SOMENTE contratos assinados) | B15: US$/mês | C15: 0 | D15: 0 | E15: 0 | F15: Regra: propostas e leads não entram. Atualizar apenas após adjudicação.
A17: Parâmetro (varia por ESTRUTURA) | B17: Unidade | C17: A - Terceirizar | D17: B - Alugar | E17: C - Comprar | F17: Fonte / status
A18: Área do imóvel | B18: sf | C18: 0 | D18: 3000 | E18: 6000 | F18: B: listagens WG/Ocoee 2.200-5.255 sf. C: comparáveis Ocoee/Apopka 6.040-6.500 sf.
A19: Capacidade de vaults | B19: vaults | C19: 100000 | D19: 100 | E19: 200 | F19: PREMISSA: ~60% da área útil, vault 7x5 ft, empilhado 2 alturas. A = capacidade do parceiro.
A20: Custo terceirizado por vault / mês | B20: US$ | C20: 60 | D20: 0 | E20: 0 | F20: PREMISSA central do cenário A: cotar com armazéns de mudança/3PL. Ver aba Sensibilidade.
A21: Aluguel base | B21: US$/sf/ano | C21: 0 | D21: 17.5 | E21: 0 | F21: LoopNet/Showcase out/2026: 661 Garden Commerce Pky US$16,50-16,75; Business Park Blvd US$17-19,20; Maguire Rd Ext Ocoee US$17. Imposto sobre aluguel comercial revogado em 01/10/2025 (HB 7031).
A22: CAM/NNN (impostos, seguro, áreas comuns) | B22: US$/sf/ano | C22: 0 | D22: 4 | E22: 0 | F22: PREMISSA: listagens não informam NNN. Confirmar com corretor.
A23: Utilidades + manutenção | B23: US$/mês | C23: 0 | D23: 600 | E23: 900 | F23: PREMISSA.
A24: Seguro warehouse legal liability | B24: US$/mês | C24: 0 | D24: 300 | E24: 300 | F24: PREMISSA: cotar com corretor de seguros.
A25: Custo fixo base (seguros auto/carga/GL, software, marketing, admin) | B25: US$/mês | C25: 3500 | D25: 3500 | E25: 3500 | F25: PENDENTE: substituir pelos custos fixos reais da Seckler.
A26: Pessoal fixo adicional do armazém | B26: US$/mês | C26: 0 | D26: 1500 | E26: 2500 | F26: PREMISSA: meio período (B) / integral parcial (C).
A27: Receita de sublocação (área excedente) | B27: US$/mês | C27: 0 | D27: 0 | E27: 3500 | F27: C: ~2.500 sf a ~US$17/sf/ano. SBA 504 exige ocupação própria (51% em imóvel existente — verificar SOP).
A28: Preço de compra | B28: US$/sf | C28: 0 | D28: 0 | E28: 300 | F28: Pedidos: 300 Story Rd Ocoee ~US$385/sf; Clarcona Rd Apopka ~US$364/sf; média WG ~US$250/sf (agregador).
A29: Entrada (equity) | B29: % do preço | C29: 0 | D29: 0 | E29: 0.1 | F29: SBA 504 padrão 10%; 15% se empresa <2 anos ou imóvel de uso especial.
... A42: Software de inventário, etiquetas, equipamentos | B42: US$ | C42: 4000 | D42: 6000 | E42: 6000 | F42: Inventário digital com fotos/código de barras é requisito prático de seguradoras.

Sheet Cenarios
A1: Resultado mensal em regime (US$) — 3 estruturas x 3 casos. Não editar: tudo é fórmula.
A2: Estrutura | B2: A - Terceirizar | C2: A - Terceirizar | D2: A - Terceirizar | E2: B - Alugar | F2: B - Alugar | G2: B - Alugar | H2: C - Comprar | I2: C - Comprar | J2: C - Comprar
A3: Caso | B3: Conservador | C3: Base | D3: Otimista | E3: Conservador | F3: Base | G3: Otimista | H3: Conservador | I3: Base | J3: Otimista
A4: RECEITA
A5: Receita de mudanças | B5: =INDEX(Premissas!$C$4:$E$4,MATCH(B$3,Premissas!$C$3:$E$3,0))*INDEX(Premissas!$C$5:$E$5,MATCH(B$3,Premissas!$C$3:$E$3,0)) | C5: =INDEX(Premissas!$C$4:$E$4,MATCH(C$3,Premissas!$C$3:$E$3,0))*INDEX(Premissas!$C$5:$E$5,MATCH(C$3,Premissas!$C$3:$E$3,0)) | D5: =INDEX(Premissas!$C$4:$E$4,MATCH(D$3,Premissas!$C$3:$E$3,0))*INDEX(Premissas!$C$5:$E$5,MATCH(D$3,Premissas!$C$3:$E$3,0)) | E5: =INDEX(Premissas!$C$4:$E$4,MATCH(E$3,Premissas!$C$3:$E$3,0))*INDEX(Premissas!$C$5:$E$5,MATCH(E$3,Premissas!$C$3:$E$3,0)) | F5: =INDEX(Premissas!$C$4:$E$4,MATCH(F$3,Premissas!$C$3:$E$3,0))*INDEX(Premissas!$C$5:$E$5,MATCH(F$3,Premissas!$C$3:$E$3,0)) | G5: =INDEX(Premissas!$C$4:$E$4,MATCH(G$3,Premissas!$C$3:$E$3,0))*INDEX(Premissas!$C$5:$E$5,MATCH(G$3,Premissas!$C$3:$E$3,0)) | H5: =INDEX(Premissas!$C$4:$E$4,MATCH(H$3,Premissas!$C$3:$E$3,0))*INDEX(Premissas!$C$5:$E$5,MATCH(H$3,Premissas!$C$3:$E$3,0)) | I5: =INDEX(Premissas!$C$4:$E$4,MATCH(I$3,Premissas!$C$3:$E$3,0))*INDEX(Premissas!$C$5:$E$5,MATCH(I$3,Premissas!$C$3:$E$3,0)) | J5: =INDEX(Premissas!$C$4:$E$4,MATCH(J$3,Premissas!$C$3:$E$3,0))*INDEX(Premissas!$C$5:$E$5,MATCH(J$3,Premissas!$C$3:$E$3,0))
A6: Receita de pack-out (sinistros) | B6: =INDEX(Premissas!$C$7:$E$7,MATCH(B$3,Premissas!$C$3:$E$3,0))*INDEX(Premissas!$C$8:$E$8,MATCH(B$3,Premissas!$C$3:$E$3,0)) | C6: =INDEX(Premissas!$C$7:$E$7,MATCH(C$3,Premissas!$C$3:$E$3,0))*INDEX(Premissas!$C$8:$E$8,MATCH(C$3,Premissas!$C$3:$E$3,0)) | D6: =INDEX(Premissas!$C$7:$E$7,MATCH(D$3,Premissas!$C$3:$E$3,0))*INDEX(Premissas!$C$8:$E$8,MATCH(D$3,Premissas!$C$3:$E$3,0)) | E6: =INDEX(Premissas!$C$7:$E$7,MATCH(E$3,Premissas!$C$3:$E$3,0))*INDEX(Premissas!$C$8:$E$8,MATCH(E$3,Premissas!$C$3:$E$3,0)) | F6: =INDEX(Premissas!$C$7:$E$7,MATCH(F$3,Premissas!$C$3:$E$3,0))*INDEX(Premissas!$C$8:$E$8,MATCH(F$3,Premissas!$C$3:$E$3,0)) | G6: =INDEX(Premissas!$C$7:$E$7,MATCH(G$3,Premissas!$C$3:$E$3,0))*INDEX(Premissas!$C$8:$E$8,MATCH(G$3,Premissas!$C$3:$E$3,0)) | H6: =INDEX(Premissas!$C$7:$E$7,MATCH(H$3,Premissas!$C$3:$E$3,0))*INDEX(Premissas!$C$8:$E$8,MATCH(H$3,Premissas!$C$3:$E$3,0)) | I6: =INDEX(Premissas!$C$7:$E$7,MATCH(I$3,Premissas!$C$3:$E$3,0))*INDEX(Premissas!$C$8:$E$8,MATCH(I$3,Premissas!$C$3:$E$3,0)) | J6: =INDEX(Premissas!$C$7:$E$7,MATCH(J$3,Premissas!$C$3:$E$3,0))*INDEX(Premissas!$C$8:$E$8,MATCH(J$3,Premissas!$C$3:$E$3,0))
A7: Vaults ocupados (limitado à capacidade) | B7: =MIN(INDEX(Premissas!$C$10:$E$10,MATCH(B$3,Premissas!$C$3:$E$3,0)),INDEX(Premissas!$C$19:$E$19,MATCH(B$2,Premissas!$C$17:$E$17,0))) | C7: =MIN(INDEX(Premissas!$C$10:$E$10,MATCH(C$3,Premissas!$C$3:$E$3,0)),INDEX(Premissas!$C$19:$E$19,MATCH(C$2,Premissas!$C$17:$E$17,0))) | D7: =MIN(INDEX(Premissas!$C$10:$E$10,MATCH(D$3,Premissas!$C$3:$E$3,0)),INDEX(Premissas!$C$19:$E$19,MATCH(D$2,Premissas!$C$17:$E$17,0))) | E7: =MIN(INDEX(Premissas!$C$10:$E$10,MATCH(E$3,Premissas!$C$3:$E$3,0)),INDEX(Premissas!$C$19:$E$19,MATCH(E$2,Premissas!$C$17:$E$17,0))) | F7: =MIN(INDEX(Premissas!$C$10:$E$10,MATCH(F$3,Premissas!$C$3:$E$3,0)),INDEX(Premissas!$C$19:$E$19,MATCH(F$2,Premissas!$C$17:$E$17,0))) | G7: =MIN(INDEX(Premissas!$C$10:$E$10,MATCH(G$3,Premissas!$C$3:$E$3,0)),INDEX(Premissas!$C$19:$E$19,MATCH(G$2,Premissas!$C$17:$E$17,0))) | H7: =MIN(INDEX(Premissas!$C$10:$E$10,MATCH(H$3,Premissas!$C$3:$E$3,0)),INDEX(Premissas!$C$19:$E$19,MATCH(H$2,Premissas!$C$17:$E$17,0))) | I7: =MIN(INDEX(Premissas!$C$10:$E$10,MATCH(I$3,Premissas!$C$3:$E$3,0)),INDEX(Premissas!$C$19:$E$19,MATCH(I$2,Premissas!$C$17:$E$17,0))) | J7: =MIN(INDEX(Premissas!$C$10:$E$10,MATCH(J$3,Premissas!$C$3:$E$3,0)),INDEX(Premissas!$C$19:$E$19,MATCH(J$2,Premissas!$C$17:$E$17,0)))
A8: Receita de armazenagem | B8: =B7*INDEX(Premissas!$C$11:$E$11,MATCH(B$3,Premissas!$C$3:$E$3,0)) | C8: =C7*INDEX(Premissas!$C$11:$E$11,MATCH(C$3,Premissas!$C$3:$E$3,0)) | D8: =D7*INDEX(Premissas!$C$11:$E$11,MATCH(D$3,Premissas!$C$3:$E$3,0)) | E8: =E7*INDEX(Premissas!$C$11:$E$11,MATCH(E$3,Premissas!$C$3:$E$3,0)) | F8: =F7*INDEX(Premissas!$C$11:$E$11,MATCH(F$3,Premissas!$C$3:$E$3,0)) | G8: =G7*INDEX(Premissas!$C$11:$E$11,MATCH(G$3,Premissas!$C$3:$E$3,0)) | H8: =H7*INDEX(Premissas!$C$11:$E$11,MATCH(H$3,Premissas!$C$3:$E$3,0)) | I8: =I7*INDEX(Premissas!$C$11:$E$11,MATCH(I$3,Premissas!$C$3:$E$3,0)) | J8: =J7*INDEX(Premissas!$C$11:$E$11,MATCH(J$3,Premissas!$C$3:$E$3,0))
A9: Receita governo (contratos assinados) | B9: =INDEX(Premissas!$C$15:$E$15,MATCH(B$3,Premissas!$C$3:$E$3,0)) | C9: =INDEX(Premissas!$C$15:$E$15,MATCH(C$3,Premissas!$C$3:$E$3,0)) | D9: =INDEX(Premissas!$C$15:$E$15,MATCH(D$3,Premissas!$C$3:$E$3,0)) | E9: =INDEX(Premissas!$C$15:$E$15,MATCH(E$3,Premissas!$C$3:$E$3,0)) | F9: =INDEX(Premissas!$C$15:$E$15,MATCH(F$3,Premissas!$C$3:$E$3,0)) | G9: =INDEX(Premissas!$C$15:$E$15,MATCH(G$3,Premissas!$C$3:$E$3,0)) | H9: =INDEX(Premissas!$C$15:$E$15,MATCH(H$3,Premissas!$C$3:$E$3,0)) | I9: =INDEX(Premissas!$C$15:$E$15,MATCH(I$3,Premissas!$C$3:$E$3,0)) | J9: =INDEX(Premissas!$C$15:$E$15,MATCH(J$3,Premissas!$C$3:$E$3,0))
A10: Receita de sublocação | B10: =INDEX(Premissas!$C$27:$E$27,MATCH(B$2,Premissas!$C$17:$E$17,0)) | C10: =INDEX(Premissas!$C$27:$E$27,MATCH(C$2,Premissas!$C$17:$E$17,0)) | D10: =INDEX(Premissas!$C$27:$E$27,MATCH(D$2,Premissas!$C$17:$E$17,0)) | E10: =INDEX(Premissas!$C$27:$E$27,MATCH(E$2,Premissas!$C$17:$E$17,0)) | F10: =INDEX(Premissas!$C$27:$E$27,MATCH(F$2,Premissas!$C$17:$E$17,0)) | G10: =INDEX(Premissas!$C$27:$E$27,MATCH(G$2,Premissas!$C$17:$E$17,0)) | H10: =INDEX(Premissas!$C$27:$E$27,MATCH(H$2,Premissas!$C$17:$E$17,0)) | I10: =INDEX(Premissas!$C$27:$E$27,MATCH(I$2,Premissas!$C$17:$E$17,0)) | J10: =INDEX(Premissas!$C$27:$E$27,MATCH(J$2,Premissas!$C$17:$E$17,0))
A11: RECEITA TOTAL | B11: =SUM(B5,B6,B8,B9,B10) | C11: =SUM(C5,C6,C8,C9,C10) | D11: =SUM(D5,D6,D8,D9,D10) | E11: =SUM(E5,E6,E8,E9,E10) | F11: =SUM(F5,F6,F8,F9,F10) | G11: =SUM(G5,G6,G8,G9,G10) | H11: =SUM(H5,H6,H8,H9,H10) | I11: =SUM(I5,I6,I8,I9,I10) | J11: =SUM(J5,J6,J8,J9,J10)
A12: CUSTOS VARIÁVEIS
A13: CV mudanças | B13: =B5*INDEX(Premissas!$C$6:$E$6,MATCH(B$3,Premissas!$C$3:$E$3,0)) | C13: =C5*INDEX(Premissas!$C$6:$E$6,MATCH(C$3,Premissas!$C$3:$E$3,0)) | D13: =D5*INDEX(Premissas!$C$6:$E$6,MATCH(D$3,Premissas!$C$3:$E$3,0)) | E13: =E5*INDEX(Premissas!$C$6:$E$6,MATCH(E$3,Premissas!$C$3:$E$3,0)) | F13: =F5*INDEX(Premissas!$C$6:$E$6,MATCH(F$3,Premissas!$C$3:$E$3,0)) | G13: =G5*INDEX(Premissas!$C$6:$E$6,MATCH(G$3,Premissas!$C$3:$E$3,0)) | H13: =H5*INDEX(Premissas!$C$6:$E$6,MATCH(H$3,Premissas!$C$3:$E$3,0)) | I13: =I5*INDEX(Premissas!$C$6:$E$6,MATCH(I$3,Premissas!$C$3:$E$3,0)) | J13: =J5*INDEX(Premissas!$C$6:$E$6,MATCH(J$3,Premissas!$C$3:$E$3,0))
A14: CV pack-out | B14: =B6*INDEX(Premissas!$C$9:$E$9,MATCH(B$3,Premissas!$C$3:$E$3,0)) | C14: =C6*INDEX(Premissas!$C$9:$E$9,MATCH(C$3,Premissas!$C$3:$E$3,0)) | D14: =D6*INDEX(Premissas!$C$9:$E$9,MATCH(D$3,Premissas!$C$3:$E$3,0)) | E14: =E6*INDEX(Premissas!$C$9:$E$9,MATCH(E$3,Premissas!$C$3:$E$3,0)) | F14: =F6*INDEX(Premissas!$C$9:$E$9,MATCH(F$3,Premissas!$C$3:$E$3,0)) | G14: =G6*INDEX(Premissas!$C$9:$E$9,MATCH(G$3,Premissas!$C$3:$E$3,0)) | H14: =H6*INDEX(Premissas!$C$9:$E$9,MATCH(H$3,Premissas!$C$3:$E$3,0)) | I14: =I6*INDEX(Premissas!$C$9:$E$9,MATCH(I$3,Premissas!$C$3:$E$3,0)) | J14: =J6*INDEX(Premissas!$C$9:$E$9,MATCH(J$3,Premissas!$C$3:$E$3,0))
A15: CV armazenagem (manuseio + custo terceirizado) | B15: =B7*(INDEX(Premissas!$C$12:$E$12,MATCH(B$3,Premissas!$C$3:$E$3,0))+INDEX(Premissas!$C$20:$E$20,MATCH(B$2,Premissas!$C$17:$E$17,0))) | C15: =C7*(INDEX(Premissas!$C$12:$E$12,MATCH(C$3,Premissas!$C$3:$E$3,0))+INDEX(Premissas!$C$20:$E$20,MATCH(C$2,Premissas!$C$17:$E$17,0))) | D15: =D7*(INDEX(Premissas!$C$12:$E$12,MATCH(D$3,Premissas!$C$3:$E$3,0))+INDEX(Premissas!$C$20:$E$20,MATCH(D$2,Premissas!$C$17:$E$17,0))) | E15: =E7*(INDEX(Premissas!$C$12:$E$12,MATCH(E$3,Premissas!$C$3:$E$3,0))+INDEX(Premissas!$C$20:$E$20,MATCH(E$2,Premissas!$C$17:$E$17,0))) | F15: =F7*(INDEX(Premissas!$C$12:$E$12,MATCH(F$3,Premissas!$C$3:$E$3,0))+INDEX(Premissas!$C$20:$E$20,MATCH(F$2,Premissas!$C$17:$E$17,0))) | G15: =G7*(INDEX(Premissas!$C$12:$E$12,MATCH(G$3,Premissas!$C$3:$E$3,0))+INDEX(Premissas!$C$20:$E$20,MATCH(G$2,Premissas!$C$17:$E$17,0))) | H15: =H7*(INDEX(Premissas!$C$12:$E$12,MATCH(H$3,Premissas!$C$3:$E$3,0))+INDEX(Premissas!$C$20:$E$20,MATCH(H$2,Premissas!$C$17:$E$17,0))) | I15: =I7*(INDEX(Premissas!$C$12:$E$12,MATCH(I$3,Premissas!$C$3:$E$3,0))+INDEX(Premissas!$C$20:$E$20,MATCH(I$2,Premissas!$C$17:$E$17,0))) | J15: =J7*(INDEX(Premissas!$C$12:$E$12,MATCH(J$3,Premissas!$C$3:$E$3,0))+INDEX(Premissas!$C$20:$E$20,MATCH(J$2,Premissas!$C$17:$E$17,0)))
A16: CV governo (premissa 60%) | B16: =B9*0.6 | C16: =C9*0.6 | D16: =D9*0.6 | E16: =E9*0.6 | F16: =F9*0.6 | G16: =G9*0.6 | H16: =H9*0.6 | I16: =I9*0.6 | J16: =J9*0.6
A17: CUSTO VARIÁVEL TOTAL | B17: =SUM(B13,B14,B15,B16) | C17: =SUM(C13,C14,C15,C16) | D17: =SUM(D13,D14,D15,D16) | E17: =SUM(E13,E14,E15,E16) | F17: =SUM(F13,F14,F15,F16) | G17: =SUM(G13,G14,G15,G16) | H17: =SUM(H13,H14,H15,H16) | I17: =SUM(I13,I14,I15,I16) | J17: =SUM(J13,J14,J15,J16)
A18: MARGEM DE CONTRIBUIÇÃO | B18: =B11-B17 | C18: =C11-C17 | D18: =D11-D17 | E18: =E11-E17 | F18: =F11-F17 | G18: =G11-G17 | H18: =H11-H17 | I18: =I11-I17 | J18: =J11-J17
A19: Margem de contribuição % | B19: =IF(B11>0,B18/B11,0) | C19: =IF(C11>0,C18/C11,0) | D19: =IF(D11>0,D18/D11,0) | E19: =IF(E11>0,E18/E11,0) | F19: =IF(F11>0,F18/F11,0) | G19: =IF(G11>0,G18/G11,0) | H19: =IF(H11>0,H18/H11,0) | I19: =IF(I11>0,I18/I11,0) | J19: =IF(J11>0,J18/J11,0)
A20: CUSTOS FIXOS (mensal)
A21: Custo fixo base | B21: =INDEX(Premissas!$C$25:$E$25,MATCH(B$2,Premissas!$C$17:$E$17,0)) | C21: =INDEX(Premissas!$C$25:$E$25,MATCH(C$2,Premissas!$C$17:$E$17,0)) | D21: =INDEX(Premissas!$C$25:$E$25,MATCH(D$2,Premissas!$C$17:$E$17,0)) | E21: =INDEX(Premissas!$C$25:$E$25,MATCH(E$2,Premissas!$C$17:$E$17,0)) | F21: =INDEX(Premissas!$C$25:$E$25,MATCH(F$2,Premissas!$C$17:$E$17,0)) | G21: =INDEX(Premissas!$C$25:$E$25,MATCH(G$2,Premissas!$C$17:$E$17,0)) | H21: =INDEX(Premissas!$C$25:$E$25,MATCH(H$2,Premissas!$C$17:$E$17,0)) | I21: =INDEX(Premissas!$C$25:$E$25,MATCH(I$2,Premissas!$C$17:$E$17,0)) | J21: =INDEX(Premissas!$C$25:$E$25,MATCH(J$2,Premissas!$C$17:$E$17,0))
A22: Aluguel + CAM | B22: =INDEX(Premissas!$C$18:$E$18,MATCH(B$2,Premissas!$C$17:$E$17,0))*(INDEX(Premissas!$C$21:$E$21,MATCH(B$2,Premissas!$C$17:$E$17,0))+INDEX(Premissas!$C$22:$E$22,MATCH(B$2,Premissas!$C$17:$E$17,0)))/12 | C22: =INDEX(Premissas!$C$18:$E$18,MATCH(C$2,Premissas!$C$17:$E$17,0))*(INDEX(Premissas!$C$21:$E$21,MATCH(C$2,Premissas!$C$17:$E$17,0))+INDEX(Premissas!$C$22:$E$22,MATCH(C$2,Premissas!$C$17:$E$17,0)))/12 | D22: =INDEX(Premissas!$C$18:$E$18,MATCH(D$2,Premissas!$C$17:$E$17,0))*(INDEX(Premissas!$C$21:$E$21,MATCH(D$2,Premissas!$C$17:$E$17,0))+INDEX(Premissas!$C$22:$E$22,MATCH(D$2,Premissas!$C$17:$E$17,0)))/12 | E22: =INDEX(Premissas!$C$18:$E$18,MATCH(E$2,Premissas!$C$17:$E$17,0))*(INDEX(Premissas!$C$21:$E$21,MATCH(E$2,Premissas!$C$17:$E$17,0))+INDEX(Premissas!$C$22:$E$22,MATCH(E$2,Premissas!$C$17:$E$17,0)))/12 | F22: =INDEX(Premissas!$C$18:$E$18,MATCH(F$2,Premissas!$C$17:$E$17,0))*(INDEX(Premissas!$C$21:$E$21,MATCH(F$2,Premissas!$C$17:$E$17,0))+INDEX(Premissas!$C$22:$E$22,MATCH(F$2,Premissas!$C$17:$E$17,0)))/12 | G22: =INDEX(Premissas!$C$18:$E$18,MATCH(G$2,Premissas!$C$17:$E$17,0))*(INDEX(Premissas!$C$21:$E$21,MATCH(G$2,Premissas!$C$17:$E$17,0))+INDEX(Premissas!$C$22:$E$22,MATCH(G$2,Premissas!$C$17:$E$17,0)))/12 | H22: =INDEX(Premissas!$C$18:$E$18,MATCH(H$2,Premissas!$C$17:$E$17,0))*(INDEX(Premissas!$C$21:$E$21,MATCH(H$2,Premissas!$C$17:$E$17,0))+INDEX(Premissas!$C$22:$E$22,MATCH(H$2,Premissas!$C$17:$E$17,0)))/12 | I22: =INDEX(Premissas!$C$18:$E$18,MATCH(I$2,Premissas!$C$17:$E$17,0))*(INDEX(Premissas!$C$21:$E$21,MATCH(I$2,Premissas!$C$17:$E$17,0))+INDEX(Premissas!$C$22:$E$22,MATCH(I$2,Premissas!$C$17:$E$17,0)))/12 | J22: =INDEX(Premissas!$C$18:$E$18,MATCH(J$2,Premissas!$C$17:$E$17,0))*(INDEX(Premissas!$C$21:$E$21,MATCH(J$2,Premissas!$C$17:$E$17,0))+INDEX(Premissas!$C$22:$E$22,MATCH(J$2,Premissas!$C$17:$E$17,0)))/12
A23: Utilidades + manutenção | B23: =INDEX(Premissas!$C$23:$E$23,MATCH(B$2,Premissas!$C$17:$E$17,0)) | C23: =INDEX(Premissas!$C$23:$E$23,MATCH(C$2,Premissas!$C$17:$E$17,0)) | D23: =INDEX(Premissas!$C$23:$E$23,MATCH(D$2,Premissas!$C$17:$E$17,0)) | E23: =INDEX(Premissas!$C$23:$E$23,MATCH(E$2,Premissas!$C$17:$E$17,0)) | F23: =INDEX(Premissas!$C$23:$E$23,MATCH(F$2,Premissas!$C$17:$E$17,0)) | G23: =INDEX(Premissas!$C$23:$E$23,MATCH(G$2,Premissas!$C$17:$E$17,0)) | H23: =INDEX(Premissas!$C$23:$E$23,MATCH(H$2,Premissas!$C$17:$E$17,0)) | I23: =INDEX(Premissas!$C$23:$E$23,MATCH(I$2,Premissas!$C$17:$E$17,0)) | J23: =INDEX(Premissas!$C$23:$E$23,MATCH(J$2,Premissas!$C$17:$E$17,0))
A24: Seguro de armazém | B24: =INDEX(Premissas!$C$24:$E$24,MATCH(B$2,Premissas!$C$17:$E$17,0)) | C24: =INDEX(Premissas!$C$24:$E$24,MATCH(C$2,Premissas!$C$17:$E$17,0)) | D24: =INDEX(Premissas!$C$24:$E$24,MATCH(D$2,Premissas!$C$17:$E$17,0)) | E24: =INDEX(Premissas!$C$24:$E$24,MATCH(E$2,Premissas!$C$17:$E$17,0)) | F24: =INDEX(Premissas!$C$24:$E$24,MATCH(F$2,Premissas!$C$17:$E$17,0)) | G24: =INDEX(Premissas!$C$24:$E$24,MATCH(G$2,Premissas!$C$17:$E$17,0)) | H24: =INDEX(Premissas!$C$24:$E$24,MATCH(H$2,Premissas!$C$17:$E$17,0)) | I24: =INDEX(Premissas!$C$24:$E$24,MATCH(I$2,Premissas!$C$17:$E$17,0)) | J24: =INDEX(Premissas!$C$24:$E$24,MATCH(J$2,Premissas!$C$17:$E$17,0))
A25: Pessoal do armazém | B25: =INDEX(Premissas!$C$26:$E$26,MATCH(B$2,Premissas!$C$17:$E$17,0)) | C25: =INDEX(Premissas!$C$26:$E$26,MATCH(C$2,Premissas!$C$17:$E$17,0)) | D25: =INDEX(Premissas!$C$26:$E$26,MATCH(D$2,Premissas!$C$17:$E$17,0)) | E25: =INDEX(Premissas!$C$26:$E$26,MATCH(E$2,Premissas!$C$17:$E$17,0)) | F25: =INDEX(Premissas!$C$26:$E$26,MATCH(F$2,Premissas!$C$17:$E$17,0)) | G25: =INDEX(Premissas!$C$26:$E$26,MATCH(G$2,Premissas!$C$17:$E$17,0)) | H25: =INDEX(Premissas!$C$26:$E$26,MATCH(H$2,Premissas!$C$17:$E$17,0)) | I25: =INDEX(Premissas!$C$26:$E$26,MATCH(I$2,Premissas!$C$17:$E$17,0)) | J25: =INDEX(Premissas!$C$26:$E$26,MATCH(J$2,Premissas!$C$17:$E$17,0))
A26: Valor do imóvel (memória) | B26: =INDEX(Premissas!$C$18:$E$18,MATCH(B$2,Premissas!$C$17:$E$17,0))*INDEX(Premissas!$C$28:$E$28,MATCH(B$2,Premissas!$C$17:$E$17,0)) | C26: =INDEX(Premissas!$C$18:$E$18,MATCH(C$2,Premissas!$C$17:$E$17,0))*INDEX(Premissas!$C$28:$E$28,MATCH(C$2,Premissas!$C$17:$E$17,0)) | D26: =INDEX(Premissas!$C$18:$E$18,MATCH(D$2,Premissas!$C$17:$E$17,0))*INDEX(Premissas!$C$28:$E$28,MATCH(D$2,Premissas!$C$17:$E$17,0)) | E26: =INDEX(Premissas!$C$18:$E$18,MATCH(E$2,Premissas!$C$17:$E$17,0))*INDEX(Premissas!$C$28:$E$28,MATCH(E$2,Premissas!$C$17:$E$17,0)) | F26: =INDEX(Premissas!$C$18:$E$18,MATCH(F$2,Premissas!$C$17:$E$17,0))*INDEX(Premissas!$C$28:$E$28,MATCH(F$2,Premissas!$C$17:$E$17,0)) | G26: =INDEX(Premissas!$C$18:$E$18,MATCH(G$2,Premissas!$C$17:$E$17,0))*INDEX(Premissas!$C$28:$E$28,MATCH(G$2,Premissas!$C$17:$E$17,0)) | H26: =INDEX(Premissas!$C$18:$E$18,MATCH(H$2,Premissas!$C$17:$E$17,0))*INDEX(Premissas!$C$28:$E$28,MATCH(H$2,Premissas!$C$17:$E$17,0)) | I26: =INDEX(Premissas!$C$18:$E$18,MATCH(I$2,Premissas!$C$17:$E$17,0))*INDEX(Premissas!$C$28:$E$28,MATCH(I$2,Premissas!$C$17:$E$17,0)) | J26: =INDEX(Premissas!$C$18:$E$18,MATCH(J$2,Premissas!$C$17:$E$17,0))*INDEX(Premissas!$C$28:$E$28,MATCH(J$2,Premissas!$C$17:$E$17,0))
A27: Parcela banco | B27: =IF(INDEX(Premissas!$C$34:$E$34,MATCH(B$2,Premissas!$C$17:$E$17,0))>0,PMT(INDEX(Premissas!$C$31:$E$31,MATCH(B$2,Premissas!$C$17:$E$17,0))/12,INDEX(Premissas!$C$34:$E$34,MATCH(B$2,Premissas!$C$17:$E$17,0))*12,-B26*INDEX(Premissas!$C$30:$E$30,MATCH(B$2,Premissas!$C$17:$E$17,0))),0) | C27: =IF(INDEX(Premissas!$C$34:$E$34,MATCH(C$2,Premissas!$C$17:$E$17,0))>0,PMT(INDEX(Premissas!$C$31:$E$31,MATCH(C$2,Premissas!$C$17:$E$17,0))/12,INDEX(Premissas!$C$34:$E$34,MATCH(C$2,Premissas!$C$17:$E$17,0))*12,-C26*INDEX(Premissas!$C$30:$E$30,MATCH(C$2,Premissas!$C$17:$E$17,0))),0) | D27: =IF(INDEX(Premissas!$C$34:$E$34,MATCH(D$2,Premissas!$C$17:$E$17,0))>0,PMT(INDEX(Premissas!$C$31:$E$31,MATCH(D$2,Premissas!$C$17:$E$17,0))/12,INDEX(Premissas!$C$34:$E$34,MATCH(D$2,Premissas!$C$17:$E$17,0))*12,-D26*INDEX(Premissas!$C$30:$E$30,MATCH(D$2,Premissas!$C$17:$E$17,0))),0) | E27: =IF(INDEX(Premissas!$C$34:$E$34,MATCH(E$2,Premissas!$C$17:$E$17,0))>0,PMT(INDEX(Premissas!$C$31:$E$31,MATCH(E$2,Premissas!$C$17:$E$17,0))/12,INDEX(Premissas!$C$34:$E$34,MATCH(E$2,Premissas!$C$17:$E$17,0))*12,-E26*INDEX(Premissas!$C$30:$E$30,MATCH(E$2,Premissas!$C$17:$E$17,0))),0) | F27: =IF(INDEX(Premissas!$C$34:$E$34,MATCH(F$2,Premissas!$C$17:$E$17,0))>0,PMT(INDEX(Premissas!$C$31:$E$31,MATCH(F$2,Premissas!$C$17:$E$17,0))/12,INDEX(Premissas!$C$34:$E$34,MATCH(F$2,Premissas!$C$17:$E$17,0))*12,-F26*INDEX(Premissas!$C$30:$E$30,MATCH(F$2,Premissas!$C$17:$E$17,0))),0) | G27: =IF(INDEX(Premissas!$C$34:$E$34,MATCH(G$2,Premissas!$C$17:$E$17,0))>0,PMT(INDEX(Premissas!$C$31:$E$31,MATCH(G$2,Premissas!$C$17:$E$17,0))/12,INDEX(Premissas!$C$34:$E$34,MATCH(G$2,Premissas!$C$17:$E$17,0))*12,-G26*INDEX(Premissas!$C$30:$E$30,MATCH(G$2,Premissas!$C$17:$E$17,0))),0) | H27: =IF(INDEX(Premissas!$C$34:$E$34,MATCH(H$2,Premissas!$C$17:$E$17,0))>0,PMT(INDEX(Premissas!$C$31:$E$31,MATCH(H$2,Premissas!$C$17:$E$17,0))/12,INDEX(Premissas!$C$34:$E$34,MATCH(H$2,Premissas!$C$17:$E$17,0))*12,-H26*INDEX(Premissas!$C$30:$E$30,MATCH(H$2,Premissas!$C$17:$E$17,0))),0) | I27: =IF(INDEX(Premissas!$C$34:$E$34,MATCH(I$2,Premissas!$C$17:$E$17,0))>0,PMT(INDEX(Premissas!$C$31:$E$31,MATCH(I$2,Premissas!$C$17:$E$17,0))/12,INDEX(Premissas!$C$34:$E$34,MATCH(I$2,Premissas!$C$17:$E$17,0))*12,-I26*INDEX(Premissas!$C$30:$E$30,MATCH(I$2,Premissas!$C$17:$E$17,0))),0) | J27: =IF(INDEX(Premissas!$C$34:$E$34,MATCH(J$2,Premissas!$C$17:$E$17,0))>0,PMT(INDEX(Premissas!$C$31:$E$31,MATCH(J$2,Premissas!$C$17:$E$17,0))/12,INDEX(Premissas!$C$34:$E$34,MATCH(J$2,Premissas!$C$17:$E$17,0))*12,-J26*INDEX(Premissas!$C$30:$E$30,MATCH(J$2,Premissas!$C$17:$E$17,0))),0)
A28: Parcela CDC/SBA 504 | B28: =IF(INDEX(Premissas!$C$34:$E$34,MATCH(B$2,Premissas!$C$17:$E$17,0))>0,PMT(INDEX(Premissas!$C$33:$E$33,MATCH(B$2,Premissas!$C$17:$E$17,0))/12,INDEX(Premissas!$C$34:$E$34,MATCH(B$2,Premissas!$C$17:$E$17,0))*12,-B26*INDEX(Premissas!$C$32:$E$32,MATCH(B$2,Premissas!$C$17:$E$17,0))),0) | C28: =IF(INDEX(Premissas!$C$34:$E$34,MATCH(C$2,Premissas!$C$17:$E$17,0))>0,PMT(INDEX(Premissas!$C$33:$E$33,MATCH(C$2,Premissas!$C$17:$E$17,0))/12,INDEX(Premissas!$C$34:$E$34,MATCH(C$2,Premissas!$C$17:$E$17,0))*12,-C26*INDEX(Premissas!$C$32:$E$32,MATCH(C$2,Premissas!$C$17:$E$17,0))),0) | D28: =IF(INDEX(Premissas!$C$34:$E$34,MATCH(D$2,Premissas!$C$17:$E$17,0))>0,PMT(INDEX(Premissas!$C$33:$E$33,MATCH(D$2,Premissas!$C$17:$E$17,0))/12,INDEX(Premissas!$C$34:$E$34,MATCH(D$2,Premissas!$C$17:$E$17,0))*12,-D26*INDEX(Premissas!$C$32:$E$32,MATCH(D$2,Premissas!$C$17:$E$17,0))),0) | E28: =IF(INDEX(Premissas!$C$34:$E$34,MATCH(E$2,Premissas!$C$17:$E$17,0))>0,PMT(INDEX(Premissas!$C$33:$E$33,MATCH(E$2,Premissas!$C$17:$E$17,0))/12,INDEX(Premissas!$C$34:$E$34,MATCH(E$2,Premissas!$C$17:$E$17,0))*12,-E26*INDEX(Premissas!$C$32:$E$32,MATCH(E$2,Premissas!$C$17:$E$17,0))),0) | F28: =IF(INDEX(Premissas!$C$34:$E$34,MATCH(F$2,Premissas!$C$17:$E$17,0))>0,PMT(INDEX(Premissas!$C$33:$E$33,MATCH(F$2,Premissas!$C$17:$E$17,0))/12,INDEX(Premissas!$C$34:$E$34,MATCH(F$2,Premissas!$C$17:$E$17,0))*12,-F26*INDEX(Premissas!$C$32:$E$32,MATCH(F$2,Premissas!$C$17:$E$17,0))),0) | G28: =IF(INDEX(Premissas!$C$34:$E$34,MATCH(G$2,Premissas!$C$17:$E$17,0))>0,PMT(INDEX(Premissas!$C$33:$E$33,MATCH(G$2,Premissas!$C$17:$E$17,0))/12,INDEX(Premissas!$C$34:$E$34,MATCH(G$2,Premissas!$C$17:$E$17,0))*12,-G26*INDEX(Premissas!$C$32:$E$32,MATCH(G$2,Premissas!$C$17:$E$17,0))),0) | H28: =IF(INDEX(Premissas!$C$34:$E$34,MATCH(H$2,Premissas!$C$17:$E$17,0))>0,PMT(INDEX(Premissas!$C$33:$E$33,MATCH(H$2,Premissas!$C$17:$E$17,0))/12,INDEX(Premissas!$C$34:$E$34,MATCH(H$2,Premissas!$C$17:$E$17,0))*12,-H26*INDEX(Premissas!$C$32:$E$32,MATCH(H$2,Premissas!$C$17:$E$17,0))),0) | I28: =IF(INDEX(Premissas!$C$34:$E$34,MATCH(I$2,Premissas!$C$17:$E$17,0))>0,PMT(INDEX(Premissas!$C$33:$E$33,MATCH(I$2,Premissas!$C$17:$E$17,0))/12,INDEX(Premissas!$C$34:$E$34,MATCH(I$2,Premissas!$C$17:$E$17,0))*12,-I26*INDEX(Premissas!$C$32:$E$32,MATCH(I$2,Premissas!$C$17:$E$17,0))),0) | J28: =IF(INDEX(Premissas!$C$34:$E$34,MATCH(J$2,Premissas!$C$17:$E$17,0))>0,PMT(INDEX(Premissas!$C$33:$E$33,MATCH(J$2,Premissas!$C$17:$E$17,0))/12,INDEX(Premissas!$C$34:$E$34,MATCH(J$2,Premissas!$C$17:$E$17,0))*12,-J26*INDEX(Premissas!$C$32:$E$32,MATCH(J$2,Premissas!$C$17:$E$17,0))),0)
A29: IPTU + seguro do imóvel | B29: =B26*INDEX(Premissas!$C$36:$E$36,MATCH(B$2,Premissas!$C$17:$E$17,0))/12 | C29: =C26*INDEX(Premissas!$C$36:$E$36,MATCH(C$2,Premissas!$C$17:$E$17,0))/12 | D29: =D26*INDEX(Premissas!$C$36:$E$36,MATCH(D$2,Premissas!$C$17:$E$17,0))/12 | E29: =E26*INDEX(Premissas!$C$36:$E$36,MATCH(E$2,Premissas!$C$17:$E$17,0))/12 | F29: =F26*INDEX(Premissas!$C$36:$E$36,MATCH(F$2,Premissas!$C$17:$E$17,0))/12 | G29: =G26*INDEX(Premissas!$C$36:$E$36,MATCH(G$2,Premissas!$C$17:$E$17,0))/12 | H29: =H26*INDEX(Premissas!$C$36:$E$36,MATCH(H$2,Premissas!$C$17:$E$17,0))/12 | I29: =I26*INDEX(Premissas!$C$36:$E$36,MATCH(I$2,Premissas!$C$17:$E$17,0))/12 | J29: =J26*INDEX(Premissas!$C$36:$E$36,MATCH(J$2,Premissas!$C$17:$E$17,0))/12
A30: CUSTO FIXO TOTAL | B30: =SUM(B21,B22,B23,B24,B25,B27,B28,B29) | C30: =SUM(C21,C22,C23,C24,C25,C27,C28,C29) | D30: =SUM(D21,D22,D23,D24,D25,D27,D28,D29) | E30: =SUM(E21,E22,E23,E24,E25,E27,E28,E29) | F30: =SUM(F21,F22,F23,F24,F25,F27,F28,F29) | G30: =SUM(G21,G22,G23,G24,G25,G27,G28,G29) | H30: =SUM(H21,H22,H23,H24,H25,H27,H28,H29) | I30: =SUM(I21,I22,I23,I24,I25,I27,I28,I29) | J30: =SUM(J21,J22,J23,J24,J25,J27,J28,J29)
A31: RESULTADO
A32: Resultado operacional de caixa / mês | B32: =B18-B30 | C32: =C18-C30 | D32: =D18-D30 | E32: =E18-E30 | F32: =F18-F30 | G32: =G18-G30 | H32: =H18-H30 | I32: =I18-I30 | J32: =J18-J30
A33: Resultado operacional de caixa / ano | B33: =B32*12 | C33: =C32*12 | D33: =D32*12 | E33: =E32*12 | F33: =F32*12 | G33: =G32*12 | H33: =H32*12 | I33: =I32*12 | J33: =J32*12
A34: Ponto de equilíbrio (receita/mês) | B34: =IF(B19>0,B30/B19,0) | C34: =IF(C19>0,C30/C19,0) | D34: =IF(D19>0,D30/D19,0) | E34: =IF(E19>0,E30/E19,0) | F34: =IF(F19>0,F30/F19,0) | G34: =IF(G19>0,G30/G19,0) | H34: =IF(H19>0,H30/H19,0) | I34: =IF(I19>0,I30/I19,0) | J34: =IF(J19>0,J30/J19,0)
A35: Vaults necessários p/ equilíbrio (demais receitas constantes) | B35: =MAX(0,(B30-(B18-B7*(INDEX(Premissas!$C$11:$E$11,MATCH(B$3,Premissas!$C$3:$E$3,0))-INDEX(Premissas!$C$12:$E$12,MATCH(B$3,Premissas!$C$3:$E$3,0))-INDEX(Premissas!$C$20:$E$20,MATCH(B$2,Premissas!$C$17:$E$17,0)))))/(INDEX(Premissas!$C$11:$E$11,MATCH(B$3,Premissas!$C$3:$E$3,0))-INDEX(Premissas!$C$12:$E$12,MATCH(B$3,Premissas!$C$3:$E$3,0))-INDEX(Premissas!$C$20:$E$20,MATCH(B$2,Premissas!$C$17:$E$17,0)))) | C35: =MAX(0,(C30-(C18-C7*(INDEX(Premissas!$C$11:$E$11,MATCH(C$3,Premissas!$C$3:$E$3,0))-INDEX(Premissas!$C$12:$E$12,MATCH(C$3,Premissas!$C$3:$E$3,0))-INDEX(Premissas!$C$20:$E$20,MATCH(C$2,Premissas!$C$17:$E$17,0)))))/(INDEX(Premissas!$C$11:$E$11,MATCH(C$3,Premissas!$C$3:$E$3,0))-INDEX(Premissas!$C$12:$E$12,MATCH(C$3,Premissas!$C$3:$E$3,0))-INDEX(Premissas!$C$20:$E$20,MATCH(C$2,Premissas!$C$17:$E$17,0)))) | D35: =MAX(0,(D30-(D18-D7*(INDEX(Premissas!$C$11:$E$11,MATCH(D$3,Premissas!$C$3:$E$3,0))-INDEX(Premissas!$C$12:$E$12,MATCH(D$3,Premissas!$C$3:$E$3,0))-INDEX(Premissas!$C$20:$E$20,MATCH(D$2,Premissas!$C$17:$E$17,0)))))/(INDEX(Premissas!$C$11:$E$11,MATCH(D$3,Premissas!$C$3:$E$3,0))-INDEX(Premissas!$C$12:$E$12,MATCH(D$3,Premissas!$C$3:$E$3,0))-INDEX(Premissas!$C$20:$E$20,MATCH(D$2,Premissas!$C$17:$E$17,0)))) | E35: =MAX(0,(E30-(E18-E7*(INDEX(Premissas!$C$11:$E$11,MATCH(E$3,Premissas!$C$3:$E$3,0))-INDEX(Premissas!$C$12:$E$12,MATCH(E$3,Premissas!$C$3:$E$3,0))-INDEX(Premissas!$C$20:$E$20,MATCH(E$2,Premissas!$C$17:$E$17,0)))))/(INDEX(Premissas!$C$11:$E$11,MATCH(E$3,Premissas!$C$3:$E$3,0))-INDEX(Premissas!$C$12:$E$12,MATCH(E$3,Premissas!$C$3:$E$3,0))-INDEX(Premissas!$C$20:$E$20,MATCH(E$2,Premissas!$C$17:$E$17,0)))) | F35: =MAX(0,(F30-(F18-F7*(INDEX(Premissas!$C$11:$E$11,MATCH(F$3,Premissas!$C$3:$E$3,0))-INDEX(Premissas!$C$12:$E$12,MATCH(F$3,Premissas!$C$3:$E$3,0))-INDEX(Premissas!$C$20:$E$20,MATCH(F$2,Premissas!$C$17:$E$17,0)))))/(INDEX(Premissas!$C$11:$E$11,MATCH(F$3,Premissas!$C$3:$E$3,0))-INDEX(Premissas!$C$12:$E$12,MATCH(F$3,Premissas!$C$3:$E$3,0))-INDEX(Premissas!$C$20:$E$20,MATCH(F$2,Premissas!$C$17:$E$17,0)))) | G35: =MAX(0,(G30-(G18-G7*(INDEX(Premissas!$C$11:$E$11,MATCH(G$3,Premissas!$C$3:$E$3,0))-INDEX(Premissas!$C$12:$E$12,MATCH(G$3,Premissas!$C$3:$E$3,0))-INDEX(Premissas!$C$20:$E$20,MATCH(G$2,Premissas!$C$17:$E$17,0)))))/(INDEX(Premissas!$C$11:$E$11,MATCH(G$3,Premissas!$C$3:$E$3,0))-INDEX(Premissas!$C$12:$E$12,MATCH(G$3,Premissas!$C$3:$E$3,0))-INDEX(Premissas!$C$20:$E$20,MATCH(G$2,Premissas!$C$17:$E$17,0)))) | H35: =MAX(0,(H30-(H18-H7*(INDEX(Premissas!$C$11:$E$11,MATCH(H$3,Premissas!$C$3:$E$3,0))-INDEX(Premissas!$C$12:$E$12,MATCH(H$3,Premissas!$C$3:$E$3,0))-INDEX(Premissas!$C$20:$E$20,MATCH(H$2,Premissas!$C$17:$E$17,0)))))/(INDEX(Premissas!$C$11:$E$11,MATCH(H$3,Premissas!$C$3:$E$3,0))-INDEX(Premissas!$C$12:$E$12,MATCH(H$3,Premissas!$C$3:$E$3,0))-INDEX(Premissas!$C$20:$E$20,MATCH(H$2,Premissas!$C$17:$E$17,0)))) | I35: =MAX(0,(I30-(I18-I7*(INDEX(Premissas!$C$11:$E$11,MATCH(I$3,Premissas!$C$3:$E$3,0))-INDEX(Premissas!$C$12:$E$12,MATCH(I$3,Premissas!$C$3:$E$3,0))-INDEX(Premissas!$C$20:$E$20,MATCH(I$2,Premissas!$C$17:$E$17,0)))))/(INDEX(Premissas!$C$11:$E$11,MATCH(I$3,Premissas!$C$3:$E$3,0))-INDEX(Premissas!$C$12:$E$12,MATCH(I$3,Premissas!$C$3:$E$3,0))-INDEX(Premissas!$C$20:$E$20,MATCH(I$2,Premissas!$C$17:$E$17,0)))) | J35: =MAX(0,(J30-(J18-J7*(INDEX(Premissas!$C$11:$E$11,MATCH(J$3,Premissas!$C$3:$E$3,0))-INDEX(Premissas!$C$12:$E$12,MATCH(J$3,Premissas!$C$3:$E$3,0))-INDEX(Premissas!$C$20:$E$20,MATCH(J$2,Premissas!$C$17:$E$17,0)))))/(INDEX(Premissas!$C$11:$E$11,MATCH(J$3,Premissas!$C$3:$E$3,0))-INDEX(Premissas!$C$12:$E$12,MATCH(J$3,Premissas!$C$3:$E$3,0))-INDEX(Premissas!$C$20:$E$20,MATCH(J$2,Premissas!$C$17:$E$17,0))))
A36: Equilíbrio cabe na capacidade? | B36: =IF(B35<=INDEX(Premissas!$C$19:$E$19,MATCH(B$2,Premissas!$C$17:$E$17,0)),"SIM","NÃO") | C36: =IF(C35<=INDEX(Premissas!$C$19:$E$19,MATCH(C$2,Premissas!$C$17:$E$17,0)),"SIM","NÃO") | D36: =IF(D35<=INDEX(Premissas!$C$19:$E$19,MATCH(D$2,Premissas!$C$17:$E$17,0)),"SIM","NÃO") | E36: =IF(E35<=INDEX(Premissas!$C$19:$E$19,MATCH(E$2,Premissas!$C$17:$E$17,0)),"SIM","NÃO") | F36: =IF(F35<=INDEX(Premissas!$C$19:$E$19,MATCH(F$2,Premissas!$C$17:$E$17,0)),"SIM","NÃO") | G36: =IF(G35<=INDEX(Premissas!$C$19:$E$19,MATCH(G$2,Premissas!$C$17:$E$17,0)),"SIM","NÃO") | H36: =IF(H35<=INDEX(Premissas!$C$19:$E$19,MATCH(H$2,Premissas!$C$17:$E$17,0)),"SIM","NÃO") | I36: =IF(I35<=INDEX(Premissas!$C$19:$E$19,MATCH(I$2,Premissas!$C$17:$E$17,0)),"SIM","NÃO") | J36: =IF(J35<=INDEX(Premissas!$C$19:$E$19,MATCH(J$2,Premissas!$C$17:$E$17,0)),"SIM","NÃO")
A37: Ocupação do armazém | B37: =IF(INDEX(Premissas!$C$19:$E$19,MATCH(B$2,Premissas!$C$17:$E$17,0))<100000,B7/INDEX(Premissas!$C$19:$E$19,MATCH(B$2,Premissas!$C$17:$E$17,0)),0) | C37: =IF(INDEX(Premissas!$C$19:$E$19,MATCH(C$2,Premissas!$C$17:$E$17,0))<100000,C7/INDEX(Premissas!$C$19:$E$19,MATCH(C$2,Premissas!$C$17:$E$17,0)),0) | D37: =IF(INDEX(Premissas!$C$19:$E$19,MATCH(D$2,Premissas!$C$17:$E$17,0))<100000,D7/INDEX(Premissas!$C$19:$E$19,MATCH(D$2,Premissas!$C$17:$E$17,0)),0) | E37: =IF(INDEX(Premissas!$C$19:$E$19,MATCH(E$2,Premissas!$C$17:$E$17,0))<100000,E7/INDEX(Premissas!$C$19:$E$19,MATCH(E$2,Premissas!$C$17:$E$17,0)),0) | F37: =IF(INDEX(Premissas!$C$19:$E$19,MATCH(F$2,Premissas!$C$17:$E$17,0))<100000,F7/INDEX(Premissas!$C$19:$E$19,MATCH(F$2,Premissas!$C$17:$E$17,0)),0) | G37: =IF(INDEX(Premissas!$C$19:$E$19,MATCH(G$2,Premissas!$C$17:$E$17,0))<100000,G7/INDEX(Premissas!$C$19:$E$19,MATCH(G$2,Premissas!$C$17:$E$17,0)),0) | H37: =IF(INDEX(Premissas!$C$19:$E$19,MATCH(H$2,Premissas!$C$17:$E$17,0))<100000,H7/INDEX(Premissas!$C$19:$E$19,MATCH(H$2,Premissas!$C$17:$E$17,0)),0) | I37: =IF(INDEX(Premissas!$C$19:$E$19,MATCH(I$2,Premissas!$C$17:$E$17,0))<100000,I7/INDEX(Premissas!$C$19:$E$19,MATCH(I$2,Premissas!$C$17:$E$17,0)),0) | J37: =IF(INDEX(Premissas!$C$19:$E$19,MATCH(J$2,Premissas!$C$17:$E$17,0))<100000,J7/INDEX(Premissas!$C$19:$E$19,MATCH(J$2,Premissas!$C$17:$E$17,0)),0)
A38: INVESTIMENTO INICIAL E CAPITAL DE GIRO
A39: Caução + 1º mês | B39: =INDEX(Premissas!$C$37:$E$37,MATCH(B$2,Premissas!$C$17:$E$17,0))*B22 | C39: =INDEX(Premissas!$C$37:$E$37,MATCH(C$2,Premissas!$C$17:$E$17,0))*C22 | D39: =INDEX(Premissas!$C$37:$E$37,MATCH(D$2,Premissas!$C$17:$E$17,0))*D22 | E39: =INDEX(Premissas!$C$37:$E$37,MATCH(E$2,Premissas!$C$17:$E$17,0))*E22 | F39: =INDEX(Premissas!$C$37:$E$37,MATCH(F$2,Premissas!$C$17:$E$17,0))*F22 | G39: =INDEX(Premissas!$C$37:$E$37,MATCH(G$2,Premissas!$C$17:$E$17,0))*G22 | H39: =INDEX(Premissas!$C$37:$E$37,MATCH(H$2,Premissas!$C$17:$E$17,0))*H22 | I39: =INDEX(Premissas!$C$37:$E$37,MATCH(I$2,Premissas!$C$17:$E$17,0))*I22 | J39: =INDEX(Premissas!$C$37:$E$37,MATCH(J$2,Premissas!$C$17:$E$17,0))*J22
A40: Entrada do imóvel | B40: =B26*INDEX(Premissas!$C$29:$E$29,MATCH(B$2,Premissas!$C$17:$E$17,0)) | C40: =C26*INDEX(Premissas!$C$29:$E$29,MATCH(C$2,Premissas!$C$17:$E$17,0)) | D40: =D26*INDEX(Premissas!$C$29:$E$29,MATCH(D$2,Premissas!$C$17:$E$17,0)) | E40: =E26*INDEX(Premissas!$C$29:$E$29,MATCH(E$2,Premissas!$C$17:$E$17,0)) | F40: =F26*INDEX(Premissas!$C$29:$E$29,MATCH(F$2,Premissas!$C$17:$E$17,0)) | G40: =G26*INDEX(Premissas!$C$29:$E$29,MATCH(G$2,Premissas!$C$17:$E$17,0)) | H40: =H26*INDEX(Premissas!$C$29:$E$29,MATCH(H$2,Premissas!$C$17:$E$17,0)) | I40: =I26*INDEX(Premissas!$C$29:$E$29,MATCH(I$2,Premissas!$C$17:$E$17,0)) | J40: =J26*INDEX(Premissas!$C$29:$E$29,MATCH(J$2,Premissas!$C$17:$E$17,0))
...

Sheet Sensibilidade
A1: Quando vale a pena ter armazém próprio? (vaults ocupados estáveis em que B ou C empatam com A)
A2: Lógica: armazém próprio troca custo variável por vault (terceirizado) por custo fixo. Indiferença = (Fixo extra da estrutura − receita de sublocação) ÷ custo terceirizado por vault.
A4: Custo terceirizado por vault/mês (A) | B4: Vaults p/ B empatar com A | C4: Capacidade B | D4: Vaults p/ C empatar com A | E4: Capacidade C
A5: 40 | B5: =ROUNDUP((Premissas!$D$18*(Premissas!$D$21+Premissas!$D$22)/12+Premissas!$D$23+Premissas!$D$24+Premissas!$D$26+IF(Premissas!$D$34>0,PMT(Premissas!$D$31/12,Premissas!$D$34*12,-(Premissas!$D$18*Premissas!$D$28)*Premissas!$D$30)+PMT(Premissas!$D$33/12,Premissas!$D$34*12,-(Premissas!$D$18*Premissas!$D$28)*Premissas!$D$32),0)+(Premissas!$D$18*Premissas!$D$28)*Premissas!$D$36/12-Premissas!$D$27)/A5,0) | C5: =Premissas!$D$19 | D5: =ROUNDUP((Premissas!$E$18*(Premissas!$E$21+Premissas!$E$22)/12+Premissas!$E$23+Premissas!$E$24+Premissas!$E$26+IF(Premissas!$E$34>0,PMT(Premissas!$E$31/12,Premissas!$E$34*12,-(Premissas!$E$18*Premissas!$E$28)*Premissas!$E$30)+PMT(Premissas!$E$33/12,Premissas!$E$34*12,-(Premissas!$E$18*Premissas!$E$28)*Premissas!$E$32),0)+(Premissas!$E$18*Premissas!$E$28)*Premissas!$E$36/12-Premissas!$E$27)/A5,0) | E5: =Premissas!$E$19
A6: 50 | B6: =ROUNDUP((Premissas!$D$18*(Premissas!$D$21+Premissas!$D$22)/12+Premissas!$D$23+Premissas!$D$24+Premissas!$D$26+IF(Premissas!$D$34>0,PMT(Premissas!$D$31/12,Premissas!$D$34*12,-(Premissas!$D$18*Premissas!$D$28)*Premissas!$D$30)+PMT(Premissas!$D$33/12,Premissas!$D$34*12,-(Premissas!$D$18*Premissas!$D$28)*Premissas!$D$32),0)+(Premissas!$D$18*Premissas!$D$28)*Premissas!$D$36/12-Premissas!$D$27)/A6,0) | C6: =Premissas!$D$19 | D6: =ROUNDUP((Premissas!$E$18*(Premissas!$E$21+Premissas!$E$22)/12+Premissas!$E$23+Premissas!$E$24+Premissas!$E$26+IF(Premissas!$E$34>0,PMT(Premissas!$E$31/12,Premissas!$E$34*12,-(Premissas!$E$18*Premissas!$E$28)*Premissas!$E$30)+PMT(Premissas!$E$33/12,Premissas!$E$34*12,-(Premissas!$E$18*Premissas!$E$28)*Premissas!$E$32),0)+(Premissas!$E$18*Premissas!$E$28)*Premissas!$E$36/12-Premissas!$E$27)/A6,0) | E6: =Premissas!$E$19
A7: 60 | B7: =ROUNDUP((Premissas!$D$18*(Premissas!$D$21+Premissas!$D$22)/12+Premissas!$D$23+Premissas!$D$24+Premissas!$D$26+IF(Premissas!$D$34>0,PMT(Premissas!$D$31/12,Premissas!$D$34*12,-(Premissas!$D$18*Premissas!$D$28)*Premissas!$D$30)+PMT(Premissas!$D$33/12,Premissas!$D$34*12,-(Premissas!$D$18*Premissas!$D$28)*Premissas!$D$32),0)+(Premissas!$D$18*Premissas!$D$28)*Premissas!$D$36/12-Premissas!$D$27)/A7,0) | C7: =Premissas!$D$19 | D7: =ROUNDUP((Premissas!$E$18*(Premissas!$E$21+Premissas!$E$22)/12+Premissas!$E$23+Premissas!$E$24+Premissas!$E$26+IF(Premissas!$E$34>0,PMT(Premissas!$E$31/12,Premissas!$E$34*12,-(Premissas!$E$18*Premissas!$E$28)*Premissas!$E$30)+PMT(Premissas!$E$33/12,Premissas!$E$34*12,-(Premissas!$E$18*Premissas!$E$28)*Premissas!$E$32),0)+(Premissas!$E$18*Premissas!$E$28)*Premissas!$E$36/12-Premissas!$E$27)/A7,0) | E7: =Premissas!$E$19
A8: 70 | B8: =ROUNDUP((Premissas!$D$18*(Premissas!$D$21+Premissas!$D$22)/12+Premissas!$D$23+Premissas!$D$24+Premissas!$D$26+IF(Premissas!$D$34>0,PMT(Premissas!$D$31/12,Premissas!$D$34*12,-(Premissas!$D$18*Premissas!$D$28)*Premissas!$D$30)+PMT(Premissas!$D$33/12,Premissas!$D$34*12,-(Premissas!$D$18*Premissas!$D$28)*Premissas!$D$32),0)+(Premissas!$D$18*Premissas!$D$28)*Premissas!$D$36/12-Premissas!$D$27)/A8,0) | C8: =Premissas!$D$19 | D8: =ROUNDUP((Premissas!$E$18*(Premissas!$E$21+Premissas!$E$22)/12+Premissas!$E$23+Premissas!$E$24+Premissas!$E$26+IF(Premissas!$E$34>0,PMT(Premissas!$E$31/12,Premissas!$E$34*12,-(Premissas!$E$18*Premissas!$E$28)*Premissas!$E$30)+PMT(Premissas!$E$33/12,Premissas!$E$34*12,-(Premissas!$E$18*Premissas!$E$28)*Premissas!$E$32),0)+(Premissas!$E$18*Premissas!$E$28)*Premissas!$E$36/12-Premissas!$E$27)/A8,0) | E8: =Premissas!$E$19
A9: 80 | B9: =ROUNDUP((Premissas!$D$18*(Premissas!$D$21+Premissas!$D$22)/12+Premissas!$D$23+Premissas!$D$24+Premissas!$D$26+IF(Premissas!$D$34>0,PMT(Premissas!$D$31/12,Premissas!$D$34*12,-(Premissas!$D$18*Premissas!$D$28)*Premissas!$D$30)+PMT(Premissas!$D$33/12,Premissas!$D$34*12,-(Premissas!$D$18*Premissas!$D$28)*Premissas!$D$32),0)+(Premissas!$D$18*Premissas!$D$28)*Premissas!$D$36/12-Premissas!$D$27)/A9,0) | C9: =Premissas!$D$19 | D9: =ROUNDUP((Premissas!$E$18*(Premissas!$E$21+Premissas!$E$22)/12+Premissas!$E$23+Premissas!$E$24+Premissas!$E$26+IF(Premissas!$E$34>0,PMT(Premissas!$E$31/12,Premissas!$E$34*12,-(Premissas!$E$18*Premissas!$E$28)*Premissas!$E$30)+PMT(Premissas!$E$33/12,Premissas!$E$34*12,-(Premissas!$E$18*Premissas!$E$28)*Premissas!$E$32),0)+(Premissas!$E$18*Premissas!$E$28)*Premissas!$E$36/12-Premissas!$E$27)/A9,0) | E9: =Premissas!$E$19
A10: 90 | B10: =ROUNDUP((Premissas!$D$18*(Premissas!$D$21+Premissas!$D$22)/12+Premissas!$D$23+Premissas!$D$24+Premissas!$D$26+IF(Premissas!$D$34>0,PMT(Premissas!$D$31/12,Premissas!$D$34*12,-(Premissas!$D$18*Premissas!$D$28)*Premissas!$D$30)+PMT(Premissas!$D$33/12,Premissas!$D$34*12,-(Premissas!$D$18*Premissas!$D$28)*Premissas!$D$32),0)+(Premissas!$D$18*Premissas!$D$28)*Premissas!$D$36/12-Premissas!$D$27)/A10,0) | C10: =Premissas!$D$19 | D10: =ROUNDUP((Premissas!$E$18*(Premissas!$E$21+Premissas!$E$22)/12+Premissas!$E$23+Premissas!$E$24+Premissas!$E$26+IF(Premissas!$E$34>0,PMT(Premissas!$E$31/12,Premissas!$E$34*12,-(Premissas!$E$18*Premissas!$E$28)*Premissas!$E$30)+PMT(Premissas!$E$33/12,Premissas!$E$34*12,-(Premissas!$E$18*Premissas!$E$28)*Premissas!$E$32),0)+(Premissas!$E$18*Premissas!$E$28)*Premissas!$E$36/12-Premissas!$E$27)/A10,0) | E10: =Premissas!$E$19
A11: 100 | B11: =ROUNDUP((Premissas!$D$18*(Premissas!$D$21+Premissas!$D$22)/12+Premissas!$D$23+Premissas!$D$24+Premissas!$D$26+IF(Premissas!$D$34>0,PMT(Premissas!$D$31/12,Premissas!$D$34*12,-(Premissas!$D$18*Premissas!$D$28)*Premissas!$D$30)+PMT(Premissas!$D$33/12,Premissas!$D$34*12,-(Premissas!$D$18*Premissas!$D$28)*Premissas!$D$32),0)+(Premissas!$D$18*Premissas!$D$28)*Premissas!$D$36/12-Premissas!$D$27)/A11,0) | C11: =Premissas!$D$19 | D11: =ROUNDUP((Premissas!$E$18*(Premissas!$E$21+Premissas!$E$22)/12+Premissas!$E$23+Premissas!$E$24+Premissas!$E$26+IF(Premissas!$E$34>0,PMT(Premissas!$E$31/12,Premissas!$E$34*12,-(Premissas!$E$18*Premissas!$E$28)*Premissas!$E$30)+PMT(Premissas!$E$33/12,Premissas!$E$34*12,-(Premissas!$E$18*Premissas!$E$28)*Premissas!$E$32),0)+(Premissas!$E$18*Premissas!$E$28)*Premissas!$E$36/12-Premissas!$E$27)/A11,0) | E11: =Premissas!$E$19
A12: 120 | B12: =ROUNDUP((Premissas!$D$18*(Premissas!$D$21+Premissas!$D$22)/12+Premissas!$D$23+Premissas!$D$24+Premissas!$D$26+IF(Premissas!$D$34>0,PMT(Premissas!$D$31/12,Premissas!$D$34*12,-(Premissas!$D$18*Premissas!$D$28)*Premissas!$D$30)+PMT(Premissas!$D$33/12,Premissas!$D$34*12,-(Premissas!$D$18*Premissas!$D$28)*Premissas!$D$32),0)+(Premissas!$D$18*Premissas!$D$28)*Premissas!$D$36/12-Premissas!$D$27)/A12,0) | C12: =Premissas!$D$19 | D12: =ROUNDUP((Premissas!$E$18*(Premissas!$E$21+Premissas!$E$22)/12+Premissas!$E$23+Premissas!$E$24+Premissas!$E$26+IF(Premissas!$E$34>0,PMT(Premissas!$E$31/12,Premissas!$E$34*12,-(Premissas!$E$18*Premissas!$E$28)*Premissas!$E$30)+PMT(Premissas!$E$33/12,Premissas!$E$34*12,-(Premissas!$E$18*Premissas!$E$28)*Premissas!$E$32),0)+(Premissas!$E$18*Premissas!$E$28)*Premissas!$E$36/12-Premissas!$E$27)/A12,0) | E12: =Premissas!$E$19
A14: Leitura: se o número de vaults para empatar for maior que a capacidade, a estrutura só se paga por outros motivos (contratos que exigem instalação própria, capacidade de pack-out, patrimônio).

Sheet CRM
A1: ID | B1: Pipeline | C1: Empresa | D1: Contato (nome/cargo) | E1: Telefone/canal público | F1: Fonte verificada | G1: Prioridade | H1: Etapa | I1: Responsável | J1: Último contato | K1: Próximo passo | L1: Data follow-up | M1: Valor potencial/mês (US$) | N1: Probabilidade | O1: Valor ponderado | P1: Notas
A2: B01 | B2: B-Sinistros | C2: SERVPRO of West Orange | E2: (407) 352-1569 | F2: https://www.servpro.com/locations/fl/servpro-of-west-orange | G2: 1 | H2: 0-Identificado | I2: Renan | K2: Ligar e pedir o responsável por contents/pack-out; perguntar se terceirizam em picos | L2: =IF(J2="","",J2+7) | O2: =IF(OR(M2="",N2=""),"",M2*N2) | P2: Franquia cobre Winter Garden e Ocoee (site oficial). SERVPRO tem processos próprios de contents; avaliar se aceita subcontratado.
A3: B02 | B3: B-Sinistros | C3: PuroClean of Winter Garden | E3: (407) 848-5888 | F3: https://www.puroclean.com/winter-garden-fl-puroclean-winter-garden/service-areas/ | G3: 1 | H3: 0-Identificado | I3: Renan | K3: Visita presencial com one-pager de pack-out | L3: =IF(J3="","",J3+7) | O3: =IF(OR(M3="",N3=""),"",M3*N3) | P3: Franquia local; programa de resposta prioritária. Tamanho e capacidade de contents não verificados.
A4: B03 | B4: B-Sinistros | C4: CEO Restoration | E4: (407) 584-7779 (Nextdoor) | F4: https://ceorestoration.com/ | G4: 1 | H4: 0-Identificado | I4: Renan | K4: Ligar; oferecer pack-out + armazenagem com inventário fotográfico | L4: =IF(J4="","",J4+7) | O4: =IF(OR(M4="",N4=""),"",M4*N4) | P4: Empresa independente sediada em Winter Garden (água/fogo/mofo). Avaliações autodeclaradas.
A5: B04 | B5: B-Sinistros | C5: FAST Restoration | E5: 9100 Conroy Windermere Rd Suite 200 | F5: https://www.bbb.org/us/fl/winter-garden/category/water-damage-restoration | G5: 1 | H5: 0-Identificado | I5: Renan | K5: Ligar; pedir reunião com gerente de operações | L5: =IF(J5="","",J5+7) | O5: =IF(OR(M5="",N5=""),"",M5*N5) | P5: BBB acreditada A+ (segundo resultado de busca); confirmar no BBB.
A6: B05 | B6: B-Sinistros | C6: All American Water Restoration | E6: ver site | F6: https://allamericanwaterrestoration.com/service-areas/winter-garden/ | G6: 2 | H6: 0-Identificado | I6: Renan | K6: Formulário/telefone do site | L6: =IF(J6="","",J6+7) | O6: =IF(OR(M6="",N6=""),"",M6*N6) | P6: Atende Ocoee/Winter Garden/Windermere. Sede e porte não verificados.
A7: B06 | B7: B-Sinistros | C7: Fortified Integrated Solutions LLC | E7: 352-856-3289 | F7: https://fisfacilityservices.com/ocoee-water-damage | G7: 2 | H7: 0-Identificado | I7: Renan | K7: Ligar | L7: =IF(J7="","",J7+7) | O7: =IF(OR(M7="",N7=""),"",M7*N7) | P7: Atende Ocoee/WG/Windermere. Porte não verificado.
A8: B07 | B8: B-Sinistros | C8: Paul Davis Restoration of Orlando | E8: ver site | F8: https://orlando.pauldavis.com/content-restoration/ | G8: 2 | H8: 0-Identificado | I8: Renan | K8: Sondar overflow em catástrofes (furacão) | L8: =IF(J8="","",J8+7) | O8: =IF(OR(M8="",N8=""),"",M8*N8) | P8: Tem centro próprio de limpeza de contents — pode ser concorrente; oportunidade de transbordo em eventos grandes.
A9: B08 | B9: B-Sinistros | C9: ServiceMaster Clean (listagem Winter Garden) | E9: (321) 441-9172 | F9: https://www.yellowpages.com/winter-garden-fl/servpro-of-winter-park | G9: 3 | H9: 0-Identificado | I9: Renan | K9: Confirmar se a franquia existe antes de contatar | L9: =IF(J9="","",J9+7) | O9: =IF(OR(M9="",N9=""),"",M9*N9) | P9: Listagem de diretório NÃO verificada no site oficial.
A10: B09 | B10: B-Sinistros | C10: Florida Property Cleaners LLC | E10: ver BBB | F10: https://www.bbb.org/us/fl/winter-garden/category/water-damage-restoration | G10: 3 | H10: 0-Identificado | I10: Renan | K10: Pesquisar porte/serviços | L10: =IF(J10="","",J10+7) | O10: =IF(OR(M10="",N10=""),"",M10*N10) | P10: Listado no BBB categoria water damage Winter Garden.
A11: B10 | B11: B-Sinistros | C11: Hero Remediation LLC | E11: ver BBB | F11: https://www.bbb.org/us/fl/winter-garden/category/water-damage-restoration | G11: 3 | H11: 0-Identificado | I11: Renan | K11: Pesquisar porte/serviços | L11: =IF(J11="","",J11+7) | O11: =IF(OR(M11="",N11=""),"",M11*N11) | P11: Listado no BBB categoria water damage Winter Garden.
A12: B11 | B12: B-Sinistros | C12: AdvantaClean of Clermont | E12: ver BBB | F12: https://www.bbb.org/us/fl/winter-garden/category/water-damage-restoration | G12: 3 | H12: 0-Identificado | I12: Renan | K12: Pesquisar porte/serviços | L12: =IF(J12="","",J12+7) | O12: =IF(OR(M12="",N12=""),"",M12*N12) | P12: Listado no BBB; cobre área oeste.
A13: A01 | B13: A-Corretores | C13: Keller Williams Realty at the Parks (Ocoee) | E13: ver Zillow | F13: https://www.zillow.com/professionals/real-estate-agent-reviews/winter-garden-fl/ | G13: 1 | H13: 0-Identificado | I13: Renan | K13: Pedir 10 min na reunião semanal de equipe (team meeting) para apresentar programa de parceria | L13: =IF(J13="","",J13+7) | O13: =IF(OR(M13="",N13=""),"",M13*N13) | P13: Zillow: 1.073 vendas da equipe em 12 meses; 189 em Winter Garden (dados do resultado de busca).
... A32: D06 | B32: D-Parceiro armazenagem | C32: UNITS Moving and Portable Storage of Orlando | E32: ver site | F32: https://unitsstorage.com/orlando-fl/warehouse-storage/ | G32: 2 | H32: 0-Identificado | I32: Renan | K32: Cotar contêineres armazenados em armazém (alternativa a vault) | L32: =IF(J32="","",J32+7) | O32: =IF(OR(M32="",N32=""),"",M32*N32) | P32: Modelo de contêiner portátil.
L33: =IF(J33="","",J33+7) | O33: =IF(OR(M33="",N33=""),"",M33*N33)
L34: =IF(J34="","",J34+7) | O34: =IF(OR(M34="",N34=""),"",M34*N34)
L35: =IF(J35="","",J35+7) | O35: =IF(OR(M35="",N35=""),"",M35*N35)
L36: =IF(J36="","",J36+7) | O36: =IF(OR(M36="",N36=""),"",M36*N36)
L37: =IF(J37="","",J37+7) | O37: =IF(OR(M37="",N37=""),"",M37*N37)
L38: =IF(J38="","",J38+7) | O38: =IF(OR(M38="",N38=""),"",M38*N38)
L39: =IF(J39="","",J39+7) | O39: =IF(OR(M39="",N39=""),"",M39*N39)
L40: =IF(J40="","",J40+7) | O40: =IF(OR(M40="",N40=""),"",M40*N40)
L41: =IF(J41="","",J41+7) | O41: =IF(OR(M41="",N41=""),"",M41*N41)
L42: =IF(J42="","",J42+7) | O42: =IF(OR(M42="",N42=""),"",M42*N42)
L43: =IF(J43="","",J43+7) | O43: =IF(OR(M43="",N43=""),"",M43*N43)
L44: =IF(J44="","",J44+7) | O44: =IF(OR(M44="",N44=""),"",M44*N44)
... L500: =IF(J500="","",J500+7) | O500: =IF(OR(M500="",N500=""),"",M500*N500)

Sheet KPIs
A1: Painel semanal — preencher toda segunda-feira (semana anterior).
A2: Semana (segunda) | B2: Contatos A (corretores) | C2: Contatos B (sinistros) | D2: Ações C (governo) | E2: Reuniões | F2: Indicações recebidas | G2: Orçamentos enviados | H2: Contratos/jobs ganhos | I2: Receita fechada (US$) | J2: Mudanças realizadas | K2: Pack-outs realizados | L2: Vaults ocupados | M2: Caixa disponível (US$) | N2: Conversão orçamento→ganho | O2: Próximas 3 ações
A3: META semanal (base) | B3: 15 | C3: 10 | D3: 3 | E3: 3 | F3: 2 | G3: 4 | H3: 2
N4: =IF(G4>0,H4/G4,"")
N5: =IF(G5>0,H5/G5,"")
N6: =IF(G6>0,H6/G6,"")
N7: =IF(G7>0,H7/G7,"")
N8: =IF(G8>0,H8/G8,"")
N9: =IF(G9>0,H9/G9,"")
N10: =IF(G10>0,H10/G10,"")
N11: =IF(G11>0,H11/G11,"")
N12: =IF(G12>0,H12/G12,"")
N13: =IF(G13>0,H13/G13,"")
N14: =IF(G14>0,H14/G14,"")
N15: =IF(G15>0,H15/G15,"")
... N55: =IF(G55>0,H55/G55,"")
A57: Acumulado 13 semanas | B57: =SUM(B4:B16) | C57: =SUM(C4:C16) | D57: =SUM(D4:D16) | E57: =SUM(E4:E16) | F57: =SUM(F4:F16) | G57: =SUM(G4:G16) | H57: =SUM(H4:H16) | I57: =SUM(I4:I16) | ... K57: =SUM(K4:K16)
